<robot name="floppy">

<material name="blue">
  <color rgba="0 0 0.8 1"/>
</material>

<material name="white">
  <color rgba="1 1 1 1"/>
</material>


  <link name="sc_bus">
    <inertial>
      <origin xyz="0 0 0" rpy="0 0 0"/>
      <mass value="10.0"/>
      <inertia ixx=".66667"  ixy="0"  ixz="0" iyy="8.33333" iyz="0" izz="8.33333" />
    </inertial>
    <visual>
      <geometry>
        <box size="3.0 1.0 1.0"/>
      </geometry>
    </visual>
  </link>


 <link name="SA1">
   <inertial>
     <origin xyz="0 1.5 0" rpy="0 0 0"/>
     <mass value="1.0"/>
     <inertia ixx="0.750833"  ixy="0"  ixz="0" iyy="0.334167" iyz="0" izz="1.08333" />
   </inertial>

   <visual>
     <origin xyz="0 1.5 0" rpy="0 0 0" />
     <geometry>
       <box size="2 3 .1" />
     </geometry>
     <material name="Cyan">
       <color rgba="0 1.0 1.0 1.0"/>
     </material>
   </visual>

 </link>

 <link name="SA2">
   <inertial>
     <origin xyz="0 1.5 0" rpy="0 0 0"/>
     <mass value="1.0"/>
     <inertia ixx="0.750833"  ixy="0"  ixz="0" iyy="0.334167" iyz="0" izz="1.08333" />
   </inertial>

   <visual>
     <origin xyz="0 1.5 0" rpy="0 0 0" />
     <geometry>
       <box size="2 3 .1" />
     </geometry>
     <material name="blue"/>
   </visual>

 </link>
 <link name="SA3">
   <inertial>
     <origin xyz="0 1.5 0" rpy="0 0 0"/>
     <mass value="1.0"/>
     <inertia ixx="0.750833"  ixy="0"  ixz="0" iyy="0.334167" iyz="0" izz="1.08333" />
   </inertial>

   <visual>
     <origin xyz="0 1.5 0" rpy="0 0 0" />
     <geometry>
       <box size="2 3 .1" />
     </geometry>
     <material name="white"/>
   </visual>

 </link>

<joint name="SA1_joint" type="continuous">
    	<parent link="sc_bus"/>
    	<child link="SA1"/>
    	<origin xyz="0 0.5 0" rpy="0 0 0"/>
    	<axis xyz="1 0 0"/>
</joint>
<joint name="SA2_joint" type="continuous">
    	<parent link="SA1"/>
    	<child link="SA2"/>
    	<origin xyz="0 3 0" rpy="0 0 0"/>
    	<axis xyz="1 0 0"/>
</joint>
<joint name="SA3_joint" type="continuous">
    	<parent link="SA2"/>
    	<child link="SA3"/>
    	<origin xyz="0 3 0" rpy="0 0 0"/>
    	<axis xyz="1 0 0"/>
</joint>

</robot>
