<robot name="multipleshapes">


  <link name="sc_bus">
    <inertial>
      <origin xyz="0 0 0" rpy="0 0 0"/>
      <mass value="1.0"/>
      <inertia ixx="1"  ixy="0"  ixz="0" iyy="2" iyz="0" izz="3" />
    </inertial>
    <visual>
      <geometry>
        <box size="3.0 1.0 1.0"/>
      </geometry>
    </visual>
  </link>


 <link name="x_arm_link">
   <inertial>
     <origin xyz="1.5 0 0" rpy="0 0 0"/>
     <mass value=".10"/>
     <inertia ixx=".1"  ixy="0"  ixz="0" iyy=".2" iyz="0" izz=".3" />
   </inertial>

   <visual>
     <origin xyz="1.5 0 0" rpy="0 0 0" />
     <geometry>
       <box size="3 .2 .2" />
     </geometry>
     <material name="Cyan">
       <color rgba="0 1.0 1.0 1.0"/>
     </material>
   </visual>

 </link>


<joint name="x_arm_joint" type="revolute">
    	<parent link="sc_bus"/>
    	<child link="x_arm_link"/>
    	<origin xyz="0 0.5 0" rpy="0 0 0"/>
    	<axis xyz="0 1 0"/>
</joint>


</robot>
